[2025-03-04T12:27:26.391-0600] {local_task_job_runner.py:123} INFO - ::group::Pre task execution logs
[2025-03-04T12:27:26.590-0600] {taskinstance.py:2614} INFO - Dependencies all met for dep_context=non-requeueable deps ti=<TaskInstance: EtlWeather.SendMessage scheduled__2025-02-24T00:00:00+00:00 [queued]>
[2025-03-04T12:27:26.699-0600] {taskinstance.py:2614} INFO - Dependencies all met for dep_context=requeueable deps ti=<TaskInstance: EtlWeather.SendMessage scheduled__2025-02-24T00:00:00+00:00 [queued]>
[2025-03-04T12:27:26.701-0600] {taskinstance.py:2867} INFO - Starting attempt 1 of 1
[2025-03-04T12:27:26.888-0600] {taskinstance.py:2890} INFO - Executing <Task(_PythonDecoratedOperator): SendMessage> on 2025-02-24 00:00:00+00:00
[2025-03-04T12:27:26.917-0600] {standard_task_runner.py:72} INFO - Started process 19662 to run task
[2025-03-04T12:27:26.919-0600] {standard_task_runner.py:104} INFO - Running: ['airflow', 'tasks', 'run', 'EtlWeather', 'SendMessage', 'scheduled__2025-02-24T00:00:00+00:00', '--job-id', '3', '--raw', '--subdir', 'DAGS_FOLDER/dataEngineering.py', '--cfg-path', '/tmp/tmps6cza7wp']
[2025-03-04T12:27:26.927-0600] {standard_task_runner.py:105} INFO - Job 3: Subtask SendMessage
[2025-03-04T12:27:27.573-0600] {task_command.py:467} INFO - Running <TaskInstance: EtlWeather.SendMessage scheduled__2025-02-24T00:00:00+00:00 [running]> on host IMNOTROY.
[2025-03-04T12:27:28.821-0600] {taskinstance.py:3134} INFO - Exporting env vars: AIRFLOW_CTX_DAG_OWNER='airflow' AIRFLOW_CTX_DAG_ID='EtlWeather' AIRFLOW_CTX_TASK_ID='SendMessage' AIRFLOW_CTX_EXECUTION_DATE='2025-02-24T00:00:00+00:00' AIRFLOW_CTX_TRY_NUMBER='1' AIRFLOW_CTX_DAG_RUN_ID='scheduled__2025-02-24T00:00:00+00:00'
[2025-03-04T12:27:28.826-0600] {taskinstance.py:732} INFO - ::endgroup::
[2025-03-04T12:28:47.745-0600] {job.py:229} INFO - Heartbeat recovered after 49.98 seconds
[2025-03-04T12:29:08.285-0600] {job.py:229} INFO - Heartbeat recovered after 23.64 seconds
[2025-03-04T12:30:52.367-0600] {job.py:229} INFO - Heartbeat recovered after 44.63 seconds
[2025-03-04T12:31:27.860-0600] {job.py:239} ERROR - Job heartbeat failed with error
Traceback (most recent call last):
  File "/home/dataScience/Projects/Pipeline/venv/lib/python3.10/site-packages/sqlalchemy/engine/base.py", line 3371, in _wrap_pool_connect
    return fn()
  File "/home/dataScience/Projects/Pipeline/venv/lib/python3.10/site-packages/sqlalchemy/pool/base.py", line 327, in connect
    return _ConnectionFairy._checkout(self)
  File "/home/dataScience/Projects/Pipeline/venv/lib/python3.10/site-packages/sqlalchemy/pool/base.py", line 894, in _checkout
    fairy = _ConnectionRecord.checkout(pool)
  File "/home/dataScience/Projects/Pipeline/venv/lib/python3.10/site-packages/sqlalchemy/pool/base.py", line 493, in checkout
    rec = pool._do_get()
  File "/home/dataScience/Projects/Pipeline/venv/lib/python3.10/site-packages/sqlalchemy/pool/impl.py", line 256, in _do_get
    return self._create_connection()
  File "/home/dataScience/Projects/Pipeline/venv/lib/python3.10/site-packages/sqlalchemy/pool/base.py", line 273, in _create_connection
    return _ConnectionRecord(self)
  File "/home/dataScience/Projects/Pipeline/venv/lib/python3.10/site-packages/sqlalchemy/pool/base.py", line 388, in __init__
    self.__connect()
  File "/home/dataScience/Projects/Pipeline/venv/lib/python3.10/site-packages/sqlalchemy/pool/base.py", line 690, in __connect
    with util.safe_reraise():
  File "/home/dataScience/Projects/Pipeline/venv/lib/python3.10/site-packages/sqlalchemy/util/langhelpers.py", line 70, in __exit__
    compat.raise_(
  File "/home/dataScience/Projects/Pipeline/venv/lib/python3.10/site-packages/sqlalchemy/util/compat.py", line 211, in raise_
    raise exception
  File "/home/dataScience/Projects/Pipeline/venv/lib/python3.10/site-packages/sqlalchemy/pool/base.py", line 686, in __connect
    self.dbapi_connection = connection = pool._invoke_creator(self)
  File "/home/dataScience/Projects/Pipeline/venv/lib/python3.10/site-packages/sqlalchemy/engine/create.py", line 574, in connect
    return dialect.connect(*cargs, **cparams)
  File "/home/dataScience/Projects/Pipeline/venv/lib/python3.10/site-packages/sqlalchemy/engine/default.py", line 598, in connect
    return self.dbapi.connect(*cargs, **cparams)
  File "/home/dataScience/Projects/Pipeline/venv/lib/python3.10/site-packages/MySQLdb/__init__.py", line 121, in Connect
    return Connection(*args, **kwargs)
  File "/home/dataScience/Projects/Pipeline/venv/lib/python3.10/site-packages/MySQLdb/connections.py", line 200, in __init__
    super().__init__(*args, **kwargs2)
MySQLdb.OperationalError: (2013, "Lost connection to MySQL server at 'reading final connect information', system error: 95")

The above exception was the direct cause of the following exception:

Traceback (most recent call last):
  File "/home/dataScience/Projects/Pipeline/venv/lib/python3.10/site-packages/airflow/jobs/job.py", line 233, in heartbeat
    heartbeat_callback(session)
  File "/home/dataScience/Projects/Pipeline/venv/lib/python3.10/site-packages/airflow/utils/session.py", line 94, in wrapper
    return func(*args, **kwargs)
  File "/home/dataScience/Projects/Pipeline/venv/lib/python3.10/site-packages/airflow/jobs/local_task_job_runner.py", line 284, in heartbeat_callback
    self.task_instance.refresh_from_db()
  File "/home/dataScience/Projects/Pipeline/venv/lib/python3.10/site-packages/airflow/utils/session.py", line 97, in wrapper
    return func(*args, session=session, **kwargs)
  File "/home/dataScience/Projects/Pipeline/venv/lib/python3.10/site-packages/airflow/models/taskinstance.py", line 2360, in refresh_from_db
    _refresh_from_db(task_instance=self, session=session, lock_for_update=lock_for_update)
  File "/home/dataScience/Projects/Pipeline/venv/lib/python3.10/site-packages/airflow/models/taskinstance.py", line 873, in _refresh_from_db
    ti = TaskInstance.get_task_instance(
  File "/home/dataScience/Projects/Pipeline/venv/lib/python3.10/site-packages/airflow/api_internal/internal_api_call.py", line 166, in wrapper
    return func(*args, **kwargs)
  File "/home/dataScience/Projects/Pipeline/venv/lib/python3.10/site-packages/airflow/utils/session.py", line 94, in wrapper
    return func(*args, **kwargs)
  File "/home/dataScience/Projects/Pipeline/venv/lib/python3.10/site-packages/airflow/models/taskinstance.py", line 2346, in get_task_instance
    return query.one_or_none()
  File "/home/dataScience/Projects/Pipeline/venv/lib/python3.10/site-packages/sqlalchemy/orm/query.py", line 2850, in one_or_none
    return self._iter().one_or_none()
  File "/home/dataScience/Projects/Pipeline/venv/lib/python3.10/site-packages/sqlalchemy/orm/query.py", line 2916, in _iter
    result = self.session.execute(
  File "/home/dataScience/Projects/Pipeline/venv/lib/python3.10/site-packages/sqlalchemy/orm/session.py", line 1716, in execute
    conn = self._connection_for_bind(bind)
  File "/home/dataScience/Projects/Pipeline/venv/lib/python3.10/site-packages/sqlalchemy/orm/session.py", line 1555, in _connection_for_bind
    return self._transaction._connection_for_bind(
  File "/home/dataScience/Projects/Pipeline/venv/lib/python3.10/site-packages/sqlalchemy/orm/session.py", line 750, in _connection_for_bind
    conn = bind.connect()
  File "/home/dataScience/Projects/Pipeline/venv/lib/python3.10/site-packages/sqlalchemy/future/engine.py", line 412, in connect
    return super(Engine, self).connect()
  File "/home/dataScience/Projects/Pipeline/venv/lib/python3.10/site-packages/sqlalchemy/engine/base.py", line 3325, in connect
    return self._connection_cls(self, close_with_result=close_with_result)
  File "/home/dataScience/Projects/Pipeline/venv/lib/python3.10/site-packages/sqlalchemy/engine/base.py", line 96, in __init__
    else engine.raw_connection()
  File "/home/dataScience/Projects/Pipeline/venv/lib/python3.10/site-packages/sqlalchemy/engine/base.py", line 3404, in raw_connection
    return self._wrap_pool_connect(self.pool.connect, _connection)
  File "/home/dataScience/Projects/Pipeline/venv/lib/python3.10/site-packages/sqlalchemy/engine/base.py", line 3374, in _wrap_pool_connect
    Connection._handle_dbapi_exception_noconnection(
  File "/home/dataScience/Projects/Pipeline/venv/lib/python3.10/site-packages/sqlalchemy/engine/base.py", line 2208, in _handle_dbapi_exception_noconnection
    util.raise_(
  File "/home/dataScience/Projects/Pipeline/venv/lib/python3.10/site-packages/sqlalchemy/util/compat.py", line 211, in raise_
    raise exception
  File "/home/dataScience/Projects/Pipeline/venv/lib/python3.10/site-packages/sqlalchemy/engine/base.py", line 3371, in _wrap_pool_connect
    return fn()
  File "/home/dataScience/Projects/Pipeline/venv/lib/python3.10/site-packages/sqlalchemy/pool/base.py", line 327, in connect
    return _ConnectionFairy._checkout(self)
  File "/home/dataScience/Projects/Pipeline/venv/lib/python3.10/site-packages/sqlalchemy/pool/base.py", line 894, in _checkout
    fairy = _ConnectionRecord.checkout(pool)
  File "/home/dataScience/Projects/Pipeline/venv/lib/python3.10/site-packages/sqlalchemy/pool/base.py", line 493, in checkout
    rec = pool._do_get()
  File "/home/dataScience/Projects/Pipeline/venv/lib/python3.10/site-packages/sqlalchemy/pool/impl.py", line 256, in _do_get
    return self._create_connection()
  File "/home/dataScience/Projects/Pipeline/venv/lib/python3.10/site-packages/sqlalchemy/pool/base.py", line 273, in _create_connection
    return _ConnectionRecord(self)
  File "/home/dataScience/Projects/Pipeline/venv/lib/python3.10/site-packages/sqlalchemy/pool/base.py", line 388, in __init__
    self.__connect()
  File "/home/dataScience/Projects/Pipeline/venv/lib/python3.10/site-packages/sqlalchemy/pool/base.py", line 690, in __connect
    with util.safe_reraise():
  File "/home/dataScience/Projects/Pipeline/venv/lib/python3.10/site-packages/sqlalchemy/util/langhelpers.py", line 70, in __exit__
    compat.raise_(
  File "/home/dataScience/Projects/Pipeline/venv/lib/python3.10/site-packages/sqlalchemy/util/compat.py", line 211, in raise_
    raise exception
  File "/home/dataScience/Projects/Pipeline/venv/lib/python3.10/site-packages/sqlalchemy/pool/base.py", line 686, in __connect
    self.dbapi_connection = connection = pool._invoke_creator(self)
  File "/home/dataScience/Projects/Pipeline/venv/lib/python3.10/site-packages/sqlalchemy/engine/create.py", line 574, in connect
    return dialect.connect(*cargs, **cparams)
  File "/home/dataScience/Projects/Pipeline/venv/lib/python3.10/site-packages/sqlalchemy/engine/default.py", line 598, in connect
    return self.dbapi.connect(*cargs, **cparams)
  File "/home/dataScience/Projects/Pipeline/venv/lib/python3.10/site-packages/MySQLdb/__init__.py", line 121, in Connect
    return Connection(*args, **kwargs)
  File "/home/dataScience/Projects/Pipeline/venv/lib/python3.10/site-packages/MySQLdb/connections.py", line 200, in __init__
    super().__init__(*args, **kwargs2)
sqlalchemy.exc.OperationalError: (MySQLdb.OperationalError) (2013, "Lost connection to MySQL server at 'reading final connect information', system error: 95")
(Background on this error at: https://sqlalche.me/e/14/e3q8)
[2025-03-04T12:32:11.861-0600] {job.py:254} ERROR - Job heartbeat failed with error. Scheduler is in unhealthy state
[2025-03-04T12:32:16.949-0600] {job.py:229} INFO - Heartbeat recovered after 100.02 seconds
[2025-03-04T12:32:29.840-0600] {python.py:240} INFO - Done. Returned value was: Done!
[2025-03-04T12:32:31.304-0600] {taskinstance.py:341} INFO - ::group::Post task execution logs
[2025-03-04T12:32:31.317-0600] {taskinstance.py:353} INFO - Marking task as SUCCESS. dag_id=EtlWeather, task_id=SendMessage, run_id=scheduled__2025-02-24T00:00:00+00:00, execution_date=20250224T000000, start_date=20250304T182726, end_date=20250304T183231
[2025-03-04T12:32:31.798-0600] {local_task_job_runner.py:266} INFO - Task exited with return code 0
[2025-03-04T12:32:31.799-0600] {standard_task_runner.py:217} INFO - Process not found (most likely exited), stop collecting metrics
[2025-03-04T12:32:31.864-0600] {local_task_job_runner.py:245} INFO - ::endgroup::
