[2025-02-27T13:14:37.374-0600] {local_task_job_runner.py:123} INFO - ::group::Pre task execution logs
[2025-02-27T13:14:37.412-0600] {taskinstance.py:2614} INFO - Dependencies all met for dep_context=non-requeueable deps ti=<TaskInstance: EtlWeather.StoreData manual__2025-02-27T19:14:29.777200+00:00 [queued]>
[2025-02-27T13:14:37.434-0600] {taskinstance.py:2614} INFO - Dependencies all met for dep_context=requeueable deps ti=<TaskInstance: EtlWeather.StoreData manual__2025-02-27T19:14:29.777200+00:00 [queued]>
[2025-02-27T13:14:37.436-0600] {taskinstance.py:2867} INFO - Starting attempt 1 of 1
[2025-02-27T13:14:37.470-0600] {taskinstance.py:2890} INFO - Executing <Task(_PythonDecoratedOperator): StoreData> on 2025-02-27 19:14:29.777200+00:00
[2025-02-27T13:14:37.478-0600] {standard_task_runner.py:72} INFO - Started process 47555 to run task
[2025-02-27T13:14:37.483-0600] {standard_task_runner.py:104} INFO - Running: ['airflow', 'tasks', 'run', 'EtlWeather', 'StoreData', 'manual__2025-02-27T19:14:29.777200+00:00', '--job-id', '29', '--raw', '--subdir', 'DAGS_FOLDER/dag_1.py', '--cfg-path', '/tmp/tmpy0fnw054']
[2025-02-27T13:14:37.485-0600] {standard_task_runner.py:105} INFO - Job 29: Subtask StoreData
[2025-02-27T13:14:37.568-0600] {task_command.py:467} INFO - Running <TaskInstance: EtlWeather.StoreData manual__2025-02-27T19:14:29.777200+00:00 [running]> on host IMNOTROY.
[2025-02-27T13:14:37.719-0600] {taskinstance.py:3134} INFO - Exporting env vars: AIRFLOW_CTX_DAG_OWNER='airflow' AIRFLOW_CTX_DAG_ID='EtlWeather' AIRFLOW_CTX_TASK_ID='StoreData' AIRFLOW_CTX_EXECUTION_DATE='2025-02-27T19:14:29.777200+00:00' AIRFLOW_CTX_TRY_NUMBER='1' AIRFLOW_CTX_DAG_RUN_ID='manual__2025-02-27T19:14:29.777200+00:00'
[2025-02-27T13:14:37.720-0600] {taskinstance.py:732} INFO - ::endgroup::
[2025-02-27T13:14:37.769-0600] {__init__.py:149} INFO - package: mysql.connector.plugins
[2025-02-27T13:14:37.770-0600] {__init__.py:150} INFO - plugin_name: caching_sha2_password
[2025-02-27T13:14:37.771-0600] {__init__.py:154} INFO - AUTHENTICATION_PLUGIN_CLASS: MySQLCachingSHA2PasswordAuthPlugin
[2025-02-27T13:14:37.772-0600] {__init__.py:149} INFO - package: mysql.connector.plugins
[2025-02-27T13:14:37.773-0600] {__init__.py:150} INFO - plugin_name: mysql_native_password
[2025-02-27T13:14:37.775-0600] {__init__.py:154} INFO - AUTHENTICATION_PLUGIN_CLASS: MySQLNativePasswordAuthPlugin
[2025-02-27T13:14:37.797-0600] {taskinstance.py:3313} ERROR - Task failed with exception
Traceback (most recent call last):
  File "/home/dataScience/Projects/Pipeline/venv/lib/python3.10/site-packages/airflow/models/taskinstance.py", line 768, in _execute_task
    result = _execute_callable(context=context, **execute_callable_kwargs)
  File "/home/dataScience/Projects/Pipeline/venv/lib/python3.10/site-packages/airflow/models/taskinstance.py", line 734, in _execute_callable
    return ExecutionCallableRunner(
  File "/home/dataScience/Projects/Pipeline/venv/lib/python3.10/site-packages/airflow/utils/operator_helpers.py", line 252, in run
    return self.func(*args, **kwargs)
  File "/home/dataScience/Projects/Pipeline/venv/lib/python3.10/site-packages/airflow/models/baseoperator.py", line 424, in wrapper
    return func(self, *args, **kwargs)
  File "/home/dataScience/Projects/Pipeline/venv/lib/python3.10/site-packages/airflow/decorators/base.py", line 266, in execute
    return_value = super().execute(context)
  File "/home/dataScience/Projects/Pipeline/venv/lib/python3.10/site-packages/airflow/models/baseoperator.py", line 424, in wrapper
    return func(self, *args, **kwargs)
  File "/home/dataScience/Projects/Pipeline/venv/lib/python3.10/site-packages/airflow/operators/python.py", line 238, in execute
    return_value = self.execute_callable()
  File "/home/dataScience/Projects/Pipeline/venv/lib/python3.10/site-packages/airflow/operators/python.py", line 256, in execute_callable
    return runner.run(*self.op_args, **self.op_kwargs)
  File "/home/dataScience/Projects/Pipeline/venv/lib/python3.10/site-packages/airflow/utils/operator_helpers.py", line 252, in run
    return self.func(*args, **kwargs)
  File "/home/dataScience/Projects/Pipeline/airflow/dags/dag_1.py", line 59, in StoreData
    cursor.execute(f"""
  File "/home/dataScience/Projects/Pipeline/venv/lib/python3.10/site-packages/mysql/connector/cursor.py", line 416, in execute
    self._connection.cmd_query(
  File "/home/dataScience/Projects/Pipeline/venv/lib/python3.10/site-packages/mysql/connector/opentelemetry/context_propagation.py", line 106, in wrapper
    result = method(cnx, *args, **kwargs)
  File "/home/dataScience/Projects/Pipeline/venv/lib/python3.10/site-packages/mysql/connector/utils.py", line 742, in handle_cnx_method
    raise err
  File "/home/dataScience/Projects/Pipeline/venv/lib/python3.10/site-packages/mysql/connector/utils.py", line 738, in handle_cnx_method
    return cnx_method(cnx, *args, **kwargs)
  File "/home/dataScience/Projects/Pipeline/venv/lib/python3.10/site-packages/mysql/connector/connection.py", line 937, in cmd_query
    result = self._handle_result(
  File "/home/dataScience/Projects/Pipeline/venv/lib/python3.10/site-packages/mysql/connector/utils.py", line 742, in handle_cnx_method
    raise err
  File "/home/dataScience/Projects/Pipeline/venv/lib/python3.10/site-packages/mysql/connector/utils.py", line 738, in handle_cnx_method
    return cnx_method(cnx, *args, **kwargs)
  File "/home/dataScience/Projects/Pipeline/venv/lib/python3.10/site-packages/mysql/connector/connection.py", line 703, in _handle_result
    raise get_exception(packet)
mysql.connector.errors.ProgrammingError: 1064 (42000): You have an error in your SQL syntax; check the manual that corresponds to your MySQL server version for the right syntax to use near '' at line 2
[2025-02-27T13:14:37.818-0600] {taskinstance.py:1226} INFO - Marking task as FAILED. dag_id=EtlWeather, task_id=StoreData, run_id=manual__2025-02-27T19:14:29.777200+00:00, execution_date=20250227T191429, start_date=20250227T191437, end_date=20250227T191437
[2025-02-27T13:14:37.876-0600] {taskinstance.py:341} INFO - ::group::Post task execution logs
[2025-02-27T13:14:37.877-0600] {standard_task_runner.py:124} ERROR - Failed to execute job 29 for task StoreData (1064 (42000): You have an error in your SQL syntax; check the manual that corresponds to your MySQL server version for the right syntax to use near '' at line 2; 47555)
Traceback (most recent call last):
  File "/home/dataScience/Projects/Pipeline/venv/lib/python3.10/site-packages/airflow/task/task_runner/standard_task_runner.py", line 117, in _start_by_fork
    ret = args.func(args, dag=self.dag)
  File "/home/dataScience/Projects/Pipeline/venv/lib/python3.10/site-packages/airflow/cli/cli_config.py", line 49, in command
    return func(*args, **kwargs)
  File "/home/dataScience/Projects/Pipeline/venv/lib/python3.10/site-packages/airflow/utils/cli.py", line 116, in wrapper
    return f(*args, **kwargs)
  File "/home/dataScience/Projects/Pipeline/venv/lib/python3.10/site-packages/airflow/cli/commands/task_command.py", line 483, in task_run
    task_return_code = _run_task_by_selected_method(args, _dag, ti)
  File "/home/dataScience/Projects/Pipeline/venv/lib/python3.10/site-packages/airflow/cli/commands/task_command.py", line 256, in _run_task_by_selected_method
    return _run_raw_task(args, ti)
  File "/home/dataScience/Projects/Pipeline/venv/lib/python3.10/site-packages/airflow/cli/commands/task_command.py", line 341, in _run_raw_task
    return ti._run_raw_task(
  File "/home/dataScience/Projects/Pipeline/venv/lib/python3.10/site-packages/airflow/utils/session.py", line 97, in wrapper
    return func(*args, session=session, **kwargs)
  File "/home/dataScience/Projects/Pipeline/venv/lib/python3.10/site-packages/airflow/models/taskinstance.py", line 3006, in _run_raw_task
    return _run_raw_task(
  File "/home/dataScience/Projects/Pipeline/venv/lib/python3.10/site-packages/airflow/models/taskinstance.py", line 274, in _run_raw_task
    TaskInstance._execute_task_with_callbacks(
  File "/home/dataScience/Projects/Pipeline/venv/lib/python3.10/site-packages/airflow/models/taskinstance.py", line 3161, in _execute_task_with_callbacks
    result = self._execute_task(context, task_orig)
  File "/home/dataScience/Projects/Pipeline/venv/lib/python3.10/site-packages/airflow/models/taskinstance.py", line 3185, in _execute_task
    return _execute_task(self, context, task_orig)
  File "/home/dataScience/Projects/Pipeline/venv/lib/python3.10/site-packages/airflow/models/taskinstance.py", line 768, in _execute_task
    result = _execute_callable(context=context, **execute_callable_kwargs)
  File "/home/dataScience/Projects/Pipeline/venv/lib/python3.10/site-packages/airflow/models/taskinstance.py", line 734, in _execute_callable
    return ExecutionCallableRunner(
  File "/home/dataScience/Projects/Pipeline/venv/lib/python3.10/site-packages/airflow/utils/operator_helpers.py", line 252, in run
    return self.func(*args, **kwargs)
  File "/home/dataScience/Projects/Pipeline/venv/lib/python3.10/site-packages/airflow/models/baseoperator.py", line 424, in wrapper
    return func(self, *args, **kwargs)
  File "/home/dataScience/Projects/Pipeline/venv/lib/python3.10/site-packages/airflow/decorators/base.py", line 266, in execute
    return_value = super().execute(context)
  File "/home/dataScience/Projects/Pipeline/venv/lib/python3.10/site-packages/airflow/models/baseoperator.py", line 424, in wrapper
    return func(self, *args, **kwargs)
  File "/home/dataScience/Projects/Pipeline/venv/lib/python3.10/site-packages/airflow/operators/python.py", line 238, in execute
    return_value = self.execute_callable()
  File "/home/dataScience/Projects/Pipeline/venv/lib/python3.10/site-packages/airflow/operators/python.py", line 256, in execute_callable
    return runner.run(*self.op_args, **self.op_kwargs)
  File "/home/dataScience/Projects/Pipeline/venv/lib/python3.10/site-packages/airflow/utils/operator_helpers.py", line 252, in run
    return self.func(*args, **kwargs)
  File "/home/dataScience/Projects/Pipeline/airflow/dags/dag_1.py", line 59, in StoreData
    cursor.execute(f"""
  File "/home/dataScience/Projects/Pipeline/venv/lib/python3.10/site-packages/mysql/connector/cursor.py", line 416, in execute
    self._connection.cmd_query(
  File "/home/dataScience/Projects/Pipeline/venv/lib/python3.10/site-packages/mysql/connector/opentelemetry/context_propagation.py", line 106, in wrapper
    result = method(cnx, *args, **kwargs)
  File "/home/dataScience/Projects/Pipeline/venv/lib/python3.10/site-packages/mysql/connector/utils.py", line 742, in handle_cnx_method
    raise err
  File "/home/dataScience/Projects/Pipeline/venv/lib/python3.10/site-packages/mysql/connector/utils.py", line 738, in handle_cnx_method
    return cnx_method(cnx, *args, **kwargs)
  File "/home/dataScience/Projects/Pipeline/venv/lib/python3.10/site-packages/mysql/connector/connection.py", line 937, in cmd_query
    result = self._handle_result(
  File "/home/dataScience/Projects/Pipeline/venv/lib/python3.10/site-packages/mysql/connector/utils.py", line 742, in handle_cnx_method
    raise err
  File "/home/dataScience/Projects/Pipeline/venv/lib/python3.10/site-packages/mysql/connector/utils.py", line 738, in handle_cnx_method
    return cnx_method(cnx, *args, **kwargs)
  File "/home/dataScience/Projects/Pipeline/venv/lib/python3.10/site-packages/mysql/connector/connection.py", line 703, in _handle_result
    raise get_exception(packet)
mysql.connector.errors.ProgrammingError: 1064 (42000): You have an error in your SQL syntax; check the manual that corresponds to your MySQL server version for the right syntax to use near '' at line 2
[2025-02-27T13:14:37.898-0600] {local_task_job_runner.py:266} INFO - Task exited with return code 1
[2025-02-27T13:14:37.918-0600] {taskinstance.py:3901} INFO - 0 downstream tasks scheduled from follow-on schedule check
[2025-02-27T13:14:37.920-0600] {local_task_job_runner.py:245} INFO - ::endgroup::
