[2025-02-27T13:05:04.239-0600] {local_task_job_runner.py:123} INFO - ::group::Pre task execution logs
[2025-02-27T13:05:04.624-0600] {taskinstance.py:2614} INFO - Dependencies all met for dep_context=non-requeueable deps ti=<TaskInstance: EtlWeather.WeatherAPI scheduled__2025-02-22T00:00:00+00:00 [queued]>
[2025-02-27T13:05:04.677-0600] {taskinstance.py:2614} INFO - Dependencies all met for dep_context=requeueable deps ti=<TaskInstance: EtlWeather.WeatherAPI scheduled__2025-02-22T00:00:00+00:00 [queued]>
[2025-02-27T13:05:04.687-0600] {taskinstance.py:2867} INFO - Starting attempt 1 of 1
[2025-02-27T13:05:05.521-0600] {taskinstance.py:2890} INFO - Executing <Task(_PythonDecoratedOperator): WeatherAPI> on 2025-02-22 00:00:00+00:00
[2025-02-27T13:05:05.600-0600] {standard_task_runner.py:72} INFO - Started process 43611 to run task
[2025-02-27T13:05:05.809-0600] {standard_task_runner.py:104} INFO - Running: ['airflow', 'tasks', 'run', 'EtlWeather', 'WeatherAPI', 'scheduled__2025-02-22T00:00:00+00:00', '--job-id', '9', '--raw', '--subdir', 'DAGS_FOLDER/dag_1.py', '--cfg-path', '/tmp/tmp4_pnn23j']
[2025-02-27T13:05:05.836-0600] {standard_task_runner.py:105} INFO - Job 9: Subtask WeatherAPI
[2025-02-27T13:05:14.186-0600] {task_command.py:467} INFO - Running <TaskInstance: EtlWeather.WeatherAPI scheduled__2025-02-22T00:00:00+00:00 [running]> on host IMNOTROY.
[2025-02-27T13:06:50.799-0600] {standard_task_runner.py:124} ERROR - Failed to execute job 9 for task WeatherAPI ((MySQLdb.OperationalError) (2013, "Lost connection to MySQL server at 'reading final connect information', system error: 95")
(Background on this error at: https://sqlalche.me/e/14/e3q8); 43611)
Traceback (most recent call last):
  File "/home/dataScience/Projects/Pipeline/venv/lib/python3.10/site-packages/sqlalchemy/engine/base.py", line 3371, in _wrap_pool_connect
    return fn()
  File "/home/dataScience/Projects/Pipeline/venv/lib/python3.10/site-packages/sqlalchemy/pool/base.py", line 327, in connect
    return _ConnectionFairy._checkout(self)
  File "/home/dataScience/Projects/Pipeline/venv/lib/python3.10/site-packages/sqlalchemy/pool/base.py", line 894, in _checkout
    fairy = _ConnectionRecord.checkout(pool)
  File "/home/dataScience/Projects/Pipeline/venv/lib/python3.10/site-packages/sqlalchemy/pool/base.py", line 493, in checkout
    rec = pool._do_get()
  File "/home/dataScience/Projects/Pipeline/venv/lib/python3.10/site-packages/sqlalchemy/pool/impl.py", line 256, in _do_get
    return self._create_connection()
  File "/home/dataScience/Projects/Pipeline/venv/lib/python3.10/site-packages/sqlalchemy/pool/base.py", line 273, in _create_connection
    return _ConnectionRecord(self)
  File "/home/dataScience/Projects/Pipeline/venv/lib/python3.10/site-packages/sqlalchemy/pool/base.py", line 388, in __init__
    self.__connect()
  File "/home/dataScience/Projects/Pipeline/venv/lib/python3.10/site-packages/sqlalchemy/pool/base.py", line 690, in __connect
    with util.safe_reraise():
  File "/home/dataScience/Projects/Pipeline/venv/lib/python3.10/site-packages/sqlalchemy/util/langhelpers.py", line 70, in __exit__
    compat.raise_(
  File "/home/dataScience/Projects/Pipeline/venv/lib/python3.10/site-packages/sqlalchemy/util/compat.py", line 211, in raise_
    raise exception
  File "/home/dataScience/Projects/Pipeline/venv/lib/python3.10/site-packages/sqlalchemy/pool/base.py", line 686, in __connect
    self.dbapi_connection = connection = pool._invoke_creator(self)
  File "/home/dataScience/Projects/Pipeline/venv/lib/python3.10/site-packages/sqlalchemy/engine/create.py", line 574, in connect
    return dialect.connect(*cargs, **cparams)
  File "/home/dataScience/Projects/Pipeline/venv/lib/python3.10/site-packages/sqlalchemy/engine/default.py", line 598, in connect
    return self.dbapi.connect(*cargs, **cparams)
  File "/home/dataScience/Projects/Pipeline/venv/lib/python3.10/site-packages/MySQLdb/__init__.py", line 121, in Connect
    return Connection(*args, **kwargs)
  File "/home/dataScience/Projects/Pipeline/venv/lib/python3.10/site-packages/MySQLdb/connections.py", line 200, in __init__
    super().__init__(*args, **kwargs2)
MySQLdb.OperationalError: (2013, "Lost connection to MySQL server at 'reading final connect information', system error: 95")

The above exception was the direct cause of the following exception:

Traceback (most recent call last):
  File "/home/dataScience/Projects/Pipeline/venv/lib/python3.10/site-packages/airflow/task/task_runner/standard_task_runner.py", line 117, in _start_by_fork
    ret = args.func(args, dag=self.dag)
  File "/home/dataScience/Projects/Pipeline/venv/lib/python3.10/site-packages/airflow/cli/cli_config.py", line 49, in command
    return func(*args, **kwargs)
  File "/home/dataScience/Projects/Pipeline/venv/lib/python3.10/site-packages/airflow/utils/cli.py", line 116, in wrapper
    return f(*args, **kwargs)
  File "/home/dataScience/Projects/Pipeline/venv/lib/python3.10/site-packages/airflow/cli/commands/task_command.py", line 483, in task_run
    task_return_code = _run_task_by_selected_method(args, _dag, ti)
  File "/home/dataScience/Projects/Pipeline/venv/lib/python3.10/site-packages/airflow/cli/commands/task_command.py", line 256, in _run_task_by_selected_method
    return _run_raw_task(args, ti)
  File "/home/dataScience/Projects/Pipeline/venv/lib/python3.10/site-packages/airflow/cli/commands/task_command.py", line 341, in _run_raw_task
    return ti._run_raw_task(
  File "/home/dataScience/Projects/Pipeline/venv/lib/python3.10/site-packages/airflow/utils/session.py", line 97, in wrapper
    return func(*args, session=session, **kwargs)
  File "/home/dataScience/Projects/Pipeline/venv/lib/python3.10/site-packages/airflow/models/taskinstance.py", line 3006, in _run_raw_task
    return _run_raw_task(
  File "/home/dataScience/Projects/Pipeline/venv/lib/python3.10/site-packages/airflow/models/taskinstance.py", line 245, in _run_raw_task
    ti.refresh_from_db(session=session)
  File "/home/dataScience/Projects/Pipeline/venv/lib/python3.10/site-packages/airflow/utils/session.py", line 94, in wrapper
    return func(*args, **kwargs)
  File "/home/dataScience/Projects/Pipeline/venv/lib/python3.10/site-packages/airflow/models/taskinstance.py", line 2360, in refresh_from_db
    _refresh_from_db(task_instance=self, session=session, lock_for_update=lock_for_update)
  File "/home/dataScience/Projects/Pipeline/venv/lib/python3.10/site-packages/airflow/models/taskinstance.py", line 873, in _refresh_from_db
    ti = TaskInstance.get_task_instance(
  File "/home/dataScience/Projects/Pipeline/venv/lib/python3.10/site-packages/airflow/api_internal/internal_api_call.py", line 166, in wrapper
    return func(*args, **kwargs)
  File "/home/dataScience/Projects/Pipeline/venv/lib/python3.10/site-packages/airflow/utils/session.py", line 94, in wrapper
    return func(*args, **kwargs)
  File "/home/dataScience/Projects/Pipeline/venv/lib/python3.10/site-packages/airflow/models/taskinstance.py", line 2346, in get_task_instance
    return query.one_or_none()
  File "/home/dataScience/Projects/Pipeline/venv/lib/python3.10/site-packages/sqlalchemy/orm/query.py", line 2850, in one_or_none
    return self._iter().one_or_none()
  File "/home/dataScience/Projects/Pipeline/venv/lib/python3.10/site-packages/sqlalchemy/orm/query.py", line 2916, in _iter
    result = self.session.execute(
  File "/home/dataScience/Projects/Pipeline/venv/lib/python3.10/site-packages/sqlalchemy/orm/session.py", line 1716, in execute
    conn = self._connection_for_bind(bind)
  File "/home/dataScience/Projects/Pipeline/venv/lib/python3.10/site-packages/sqlalchemy/orm/session.py", line 1555, in _connection_for_bind
    return self._transaction._connection_for_bind(
  File "/home/dataScience/Projects/Pipeline/venv/lib/python3.10/site-packages/sqlalchemy/orm/session.py", line 750, in _connection_for_bind
    conn = bind.connect()
  File "/home/dataScience/Projects/Pipeline/venv/lib/python3.10/site-packages/sqlalchemy/future/engine.py", line 412, in connect
    return super(Engine, self).connect()
  File "/home/dataScience/Projects/Pipeline/venv/lib/python3.10/site-packages/sqlalchemy/engine/base.py", line 3325, in connect
    return self._connection_cls(self, close_with_result=close_with_result)
  File "/home/dataScience/Projects/Pipeline/venv/lib/python3.10/site-packages/sqlalchemy/engine/base.py", line 96, in __init__
    else engine.raw_connection()
  File "/home/dataScience/Projects/Pipeline/venv/lib/python3.10/site-packages/sqlalchemy/engine/base.py", line 3404, in raw_connection
    return self._wrap_pool_connect(self.pool.connect, _connection)
  File "/home/dataScience/Projects/Pipeline/venv/lib/python3.10/site-packages/sqlalchemy/engine/base.py", line 3374, in _wrap_pool_connect
    Connection._handle_dbapi_exception_noconnection(
  File "/home/dataScience/Projects/Pipeline/venv/lib/python3.10/site-packages/sqlalchemy/engine/base.py", line 2208, in _handle_dbapi_exception_noconnection
    util.raise_(
  File "/home/dataScience/Projects/Pipeline/venv/lib/python3.10/site-packages/sqlalchemy/util/compat.py", line 211, in raise_
    raise exception
  File "/home/dataScience/Projects/Pipeline/venv/lib/python3.10/site-packages/sqlalchemy/engine/base.py", line 3371, in _wrap_pool_connect
    return fn()
  File "/home/dataScience/Projects/Pipeline/venv/lib/python3.10/site-packages/sqlalchemy/pool/base.py", line 327, in connect
    return _ConnectionFairy._checkout(self)
  File "/home/dataScience/Projects/Pipeline/venv/lib/python3.10/site-packages/sqlalchemy/pool/base.py", line 894, in _checkout
    fairy = _ConnectionRecord.checkout(pool)
  File "/home/dataScience/Projects/Pipeline/venv/lib/python3.10/site-packages/sqlalchemy/pool/base.py", line 493, in checkout
    rec = pool._do_get()
  File "/home/dataScience/Projects/Pipeline/venv/lib/python3.10/site-packages/sqlalchemy/pool/impl.py", line 256, in _do_get
    return self._create_connection()
  File "/home/dataScience/Projects/Pipeline/venv/lib/python3.10/site-packages/sqlalchemy/pool/base.py", line 273, in _create_connection
    return _ConnectionRecord(self)
  File "/home/dataScience/Projects/Pipeline/venv/lib/python3.10/site-packages/sqlalchemy/pool/base.py", line 388, in __init__
    self.__connect()
  File "/home/dataScience/Projects/Pipeline/venv/lib/python3.10/site-packages/sqlalchemy/pool/base.py", line 690, in __connect
    with util.safe_reraise():
  File "/home/dataScience/Projects/Pipeline/venv/lib/python3.10/site-packages/sqlalchemy/util/langhelpers.py", line 70, in __exit__
    compat.raise_(
  File "/home/dataScience/Projects/Pipeline/venv/lib/python3.10/site-packages/sqlalchemy/util/compat.py", line 211, in raise_
    raise exception
  File "/home/dataScience/Projects/Pipeline/venv/lib/python3.10/site-packages/sqlalchemy/pool/base.py", line 686, in __connect
    self.dbapi_connection = connection = pool._invoke_creator(self)
  File "/home/dataScience/Projects/Pipeline/venv/lib/python3.10/site-packages/sqlalchemy/engine/create.py", line 574, in connect
    return dialect.connect(*cargs, **cparams)
  File "/home/dataScience/Projects/Pipeline/venv/lib/python3.10/site-packages/sqlalchemy/engine/default.py", line 598, in connect
    return self.dbapi.connect(*cargs, **cparams)
  File "/home/dataScience/Projects/Pipeline/venv/lib/python3.10/site-packages/MySQLdb/__init__.py", line 121, in Connect
    return Connection(*args, **kwargs)
  File "/home/dataScience/Projects/Pipeline/venv/lib/python3.10/site-packages/MySQLdb/connections.py", line 200, in __init__
    super().__init__(*args, **kwargs2)
sqlalchemy.exc.OperationalError: (MySQLdb.OperationalError) (2013, "Lost connection to MySQL server at 'reading final connect information', system error: 95")
(Background on this error at: https://sqlalche.me/e/14/e3q8)
[2025-02-27T13:06:51.391-0600] {job.py:229} INFO - Heartbeat recovered after 110.11 seconds
[2025-02-27T13:06:51.804-0600] {local_task_job_runner.py:266} INFO - Task exited with return code 1
[2025-02-27T13:06:52.668-0600] {taskinstance.py:3901} INFO - 0 downstream tasks scheduled from follow-on schedule check
[2025-02-27T13:06:52.682-0600] {local_task_job_runner.py:245} INFO - ::endgroup::
[2025-02-27T13:06:54.834-0600] {standard_task_runner.py:217} INFO - Process not found (most likely exited), stop collecting metrics
