[2025-03-04T12:36:40.500-0600] {local_task_job_runner.py:123} INFO - ::group::Pre task execution logs
[2025-03-04T12:36:40.553-0600] {taskinstance.py:2614} INFO - Dependencies all met for dep_context=non-requeueable deps ti=<TaskInstance: EtlWeather.WeatherAPI manual__2025-03-04T18:36:34.170450+00:00 [queued]>
[2025-03-04T12:36:40.573-0600] {taskinstance.py:2614} INFO - Dependencies all met for dep_context=requeueable deps ti=<TaskInstance: EtlWeather.WeatherAPI manual__2025-03-04T18:36:34.170450+00:00 [queued]>
[2025-03-04T12:36:40.574-0600] {taskinstance.py:2867} INFO - Starting attempt 1 of 1
[2025-03-04T12:36:40.614-0600] {taskinstance.py:2890} INFO - Executing <Task(_PythonDecoratedOperator): WeatherAPI> on 2025-03-04 18:36:34.170450+00:00
[2025-03-04T12:36:40.622-0600] {standard_task_runner.py:72} INFO - Started process 24154 to run task
[2025-03-04T12:36:40.635-0600] {standard_task_runner.py:104} INFO - Running: ['airflow', 'tasks', 'run', 'EtlWeather', 'WeatherAPI', 'manual__2025-03-04T18:36:34.170450+00:00', '--job-id', '28', '--raw', '--subdir', 'DAGS_FOLDER/dataEngineering.py', '--cfg-path', '/tmp/tmpstvm8rdq']
[2025-03-04T12:36:40.639-0600] {standard_task_runner.py:105} INFO - Job 28: Subtask WeatherAPI
[2025-03-04T12:36:40.749-0600] {task_command.py:467} INFO - Running <TaskInstance: EtlWeather.WeatherAPI manual__2025-03-04T18:36:34.170450+00:00 [running]> on host IMNOTROY.
[2025-03-04T12:36:40.948-0600] {taskinstance.py:3134} INFO - Exporting env vars: AIRFLOW_CTX_DAG_OWNER='airflow' AIRFLOW_CTX_DAG_ID='EtlWeather' AIRFLOW_CTX_TASK_ID='WeatherAPI' AIRFLOW_CTX_EXECUTION_DATE='2025-03-04T18:36:34.170450+00:00' AIRFLOW_CTX_TRY_NUMBER='1' AIRFLOW_CTX_DAG_RUN_ID='manual__2025-03-04T18:36:34.170450+00:00'
[2025-03-04T12:36:40.952-0600] {taskinstance.py:732} INFO - ::endgroup::
[2025-03-04T12:36:41.541-0600] {python.py:240} INFO - Done. Returned value was: Error!
[2025-03-04T12:36:41.558-0600] {taskinstance.py:3313} ERROR - Task failed with exception
Traceback (most recent call last):
  File "/home/dataScience/Projects/Pipeline/venv/lib/python3.10/site-packages/airflow/models/taskinstance.py", line 778, in _execute_task
    raise AirflowException(
airflow.exceptions.AirflowException: Returned output was type <class 'str'> expected dictionary for multiple_outputs
[2025-03-04T12:36:41.565-0600] {taskinstance.py:1226} INFO - Marking task as FAILED. dag_id=EtlWeather, task_id=WeatherAPI, run_id=manual__2025-03-04T18:36:34.170450+00:00, execution_date=20250304T183634, start_date=20250304T183640, end_date=20250304T183641
[2025-03-04T12:36:41.677-0600] {taskinstance.py:341} INFO - ::group::Post task execution logs
[2025-03-04T12:36:41.678-0600] {standard_task_runner.py:124} ERROR - Failed to execute job 28 for task WeatherAPI (Returned output was type <class 'str'> expected dictionary for multiple_outputs; 24154)
Traceback (most recent call last):
  File "/home/dataScience/Projects/Pipeline/venv/lib/python3.10/site-packages/airflow/task/task_runner/standard_task_runner.py", line 117, in _start_by_fork
    ret = args.func(args, dag=self.dag)
  File "/home/dataScience/Projects/Pipeline/venv/lib/python3.10/site-packages/airflow/cli/cli_config.py", line 49, in command
    return func(*args, **kwargs)
  File "/home/dataScience/Projects/Pipeline/venv/lib/python3.10/site-packages/airflow/utils/cli.py", line 116, in wrapper
    return f(*args, **kwargs)
  File "/home/dataScience/Projects/Pipeline/venv/lib/python3.10/site-packages/airflow/cli/commands/task_command.py", line 483, in task_run
    task_return_code = _run_task_by_selected_method(args, _dag, ti)
  File "/home/dataScience/Projects/Pipeline/venv/lib/python3.10/site-packages/airflow/cli/commands/task_command.py", line 256, in _run_task_by_selected_method
    return _run_raw_task(args, ti)
  File "/home/dataScience/Projects/Pipeline/venv/lib/python3.10/site-packages/airflow/cli/commands/task_command.py", line 341, in _run_raw_task
    return ti._run_raw_task(
  File "/home/dataScience/Projects/Pipeline/venv/lib/python3.10/site-packages/airflow/utils/session.py", line 97, in wrapper
    return func(*args, session=session, **kwargs)
  File "/home/dataScience/Projects/Pipeline/venv/lib/python3.10/site-packages/airflow/models/taskinstance.py", line 3006, in _run_raw_task
    return _run_raw_task(
  File "/home/dataScience/Projects/Pipeline/venv/lib/python3.10/site-packages/airflow/models/taskinstance.py", line 274, in _run_raw_task
    TaskInstance._execute_task_with_callbacks(
  File "/home/dataScience/Projects/Pipeline/venv/lib/python3.10/site-packages/airflow/models/taskinstance.py", line 3161, in _execute_task_with_callbacks
    result = self._execute_task(context, task_orig)
  File "/home/dataScience/Projects/Pipeline/venv/lib/python3.10/site-packages/airflow/models/taskinstance.py", line 3185, in _execute_task
    return _execute_task(self, context, task_orig)
  File "/home/dataScience/Projects/Pipeline/venv/lib/python3.10/site-packages/airflow/models/taskinstance.py", line 778, in _execute_task
    raise AirflowException(
airflow.exceptions.AirflowException: Returned output was type <class 'str'> expected dictionary for multiple_outputs
[2025-03-04T12:36:41.732-0600] {local_task_job_runner.py:266} INFO - Task exited with return code 1
[2025-03-04T12:36:41.792-0600] {taskinstance.py:3901} INFO - 0 downstream tasks scheduled from follow-on schedule check
[2025-03-04T12:36:41.812-0600] {local_task_job_runner.py:245} INFO - ::endgroup::
